Workbook

Sheet Inputs
A1: Koh Tao – Standard Value KPI (2567 vs 2568) | All-in Cost, Fuel Intensity, Cost Breakdown
A2: Definitions: Total Cost = Fuel Cost + Rental + Maintenance + Other All-in Cost (THB/kWh) = Total Cost / Energy (kWh) Fuel Intensity (L/kWh) = Fuel (L) / Energy (kWh)
A4: Month (TH) | B4: Month | C4: Fuel (L) 2567 | D4: Fuel Cost (THB) 2567 | E4: Energy (kWh) 2567 | F4: Fuel Cost /Energy | G4: Rental (THB) 2567 | H4: Maint. (THB) 2567 | I4: Other (THB) 2567 | J4: Total Cost (THB) 2567 | K4: All-in (THB/kWh) 2567 | L4: Fuel Intensity (L/kWh) 2567 | M4: Total Cost (M THB) 2567 | N4: Fuel (L) 2568 | O4: Fuel Cost (THB) 2568 | P4: Energy (kWh) 2568 | Q4: Fuel Cost /Energy | R4: Rental (THB) 2568 | S4: Maint. (THB) 2568 | T4: Other (THB) 2568 | U4: Total Cost (THB) 2568 | V4: All-in (THB/kWh) 2568 | W4: Fuel Intensity (L/kWh) 2568 | X4: Total Cost (M THB) 2568 | Y4: Δ Total Cost (THB) | Z4: Δ All-in (THB/kWh) | AA4: Δ Fuel Intensity (L/kWh)
A5: มกราคม | B5: Jan | C5: 1072597 | D5: 37540895 | E5: 3686134 | F5: =D5/E5 -> 10.184354 | G5: 1850000 | H5: 21220 | I5: 409256 | J5: =D5+G5+H5+I5 -> 39821371 | K5: =IFERROR(J5/E5,0) -> 10.803018 | L5: =IFERROR(C5/E5,0) -> 0.29098155 | M5: =J5/1000000 -> 39.821371 | N5: 1169527 | O5: 40933445 | P5: 3992188 | Q5: =O5/P5 -> 10.253386 | R5: 1848000 | S5: 0 | T5: 323471 | U5: =O5+R5+S5+T5 -> 43104916 | V5: =IFERROR(U5/P5,0) -> 10.797316 | W5: =IFERROR(N5/P5,0) -> 0.29295389 | X5: =U5/1000000 -> 43.104916 | Y5: =U5-J5 -> 3283545 | Z5: =V5-K5 -> -0.0057015832 | AA5: =W5-L5 -> 0.0019723348
A6: กุมภาพันธ์ | B6: Feb | C6: 1110275 | D6: 38859625 | E6: 3823863.6 | F6: =D6/E6 -> 10.162398 | G6: 1850000 | H6: 0 | I6: 513250 | J6: =D6+G6+H6+I6 -> 41222875 | K6: =IFERROR(J6/E6,0) -> 10.780425 | L6: =IFERROR(C6/E6,0) -> 0.29035424 | M6: =J6/1000000 -> 41.222875 | N6: 1082391 | O6: 37883685 | P6: 3716275.5 | Q6: =O6/P6 -> 10.193993 | R6: 1848000 | S6: 379023.74 | T6: 370779 | U6: =O6+R6+S6+T6 -> 40481488 | V6: =IFERROR(U6/P6,0) -> 10.893027 | W6: =IFERROR(N6/P6,0) -> 0.29125693 | X6: =U6/1000000 -> 40.481488 | Y6: =U6-J6 -> -741387.26 | Z6: =V6-K6 -> 0.1126015 | AA6: =W6-L6 -> 0.00090269431
A7: มีนาคม | B7: Mar | C7: 1352019 | D7: 47320665 | E7: 4647498.7 | F7: =D7/E7 -> 10.181964 | G7: 1850000 | H7: 0 | I7: 484291 | J7: =D7+G7+H7+I7 -> 49654956 | K7: =IFERROR(J7/E7,0) -> 10.684232 | L7: =IFERROR(C7/E7,0) -> 0.29091326 | M7: =J7/1000000 -> 49.654956 | N7: 1334871 | O7: 46720485 | P7: 4670596.9 | Q7: =O7/P7 -> 10.003108 | R7: 1848000 | S7: 299.6 | T7: 321161 | U7: =O7+R7+S7+T7 -> 48889946 | V7: =IFERROR(U7/P7,0) -> 10.467601 | W7: =IFERROR(N7/P7,0) -> 0.28580308 | X7: =U7/1000000 -> 48.889946 | Y7: =U7-J7 -> -765010.4 | Z7: =V7-K7 -> -0.21663139 | AA7: =W7-L7 -> -0.0051101817
A8: เมษายน | B8: Apr | C8: 1423929 | D8: 49837515 | E8: 4892890.5 | F8: =D8/E8 -> 10.1857 | G8: 1850000 | H8: 20000 | I8: 525955 | J8: =D8+G8+H8+I8 -> 52233470 | K8: =IFERROR(J8/E8,0) -> 10.675381 | L8: =IFERROR(C8/E8,0) -> 0.29102 | M8: =J8/1000000 -> 52.23347 | N8: 1375203 | O8: 48132105 | P8: 4630957.3 | Q8: =O8/P8 -> 10.393554 | R8: 1848000 | S8: 87381 | T8: 359561 | U8: =O8+R8+S8+T8 -> 50427047 | V8: =IFERROR(U8/P8,0) -> 10.889119 | W8: =IFERROR(N8/P8,0) -> 0.29695869 | X8: =U8/1000000 -> 50.427047 | Y8: =U8-J8 -> -1806423 | Z8: =V8-K8 -> 0.21373846 | AA8: =W8-L8 -> 0.0059386858
A9: พฤษภาคม | B9: May | C9: 1338059 | D9: 46832065 | E9: 4595579.4 | F9: =D9/E9 -> 10.190677 | G9: 1850000 | H9: 0 | I9: 544185 | J9: =D9+G9+H9+I9 -> 49226250 | K9: =IFERROR(J9/E9,0) -> 10.711653 | L9: =IFERROR(C9/E9,0) -> 0.2911622 | M9: =J9/1000000 -> 49.22625 | N9: 1245931 | O9: 43607585 | P9: 4301887 | Q9: =O9/P9 -> 10.13685 | R9: 1848000 | S9: 20650 | T9: 331897 | U9: =O9+R9+S9+T9 -> 45808132 | V9: =IFERROR(U9/P9,0) -> 10.648381 | W9: =IFERROR(N9/P9,0) -> 0.2896243 | X9: =U9/1000000 -> 45.808132 | Y9: =U9-J9 -> -3418118 | Z9: =V9-K9 -> -0.0632715 | AA9: =W9-L9 -> -0.0015378995
A10: มิถุนายน | B10: Jun | C10: 1130109 | D10: 39553815 | E10: 3894982 | F10: =D10/E10 -> 10.15507 | G10: 1850000 | H10: 36016 | I10: 563841 | J10: =D10+G10+H10+I10 -> 42003672 | K10: =IFERROR(J10/E10,0) -> 10.784048 | L10: =IFERROR(C10/E10,0) -> 0.29014486 | M10: =J10/1000000 -> 42.003672 | N10: 1134880 | O10: 39720800 | P10: 3939876.7 | Q10: =O10/P10 -> 10.081737 | R10: 1848000 | S10: 6715 | T10: 427853 | U10: =O10+R10+S10+T10 -> 42003368 | V10: =IFERROR(U10/P10,0) -> 10.661087 | W10: =IFERROR(N10/P10,0) -> 0.28804962 | X10: =U10/1000000 -> 42.003368 | Y10: =U10-J10 -> -304 | Z10: =V10-K10 -> -0.12296085 | AA10: =W10-L10 -> -0.0020952347
A11: กรกฎาคม | B11: Jul | C11: 1237505 | D11: 43312675 | E11: 4260420.9 | F11: =D11/E11 -> 10.16629 | G11: 1849000 | H11: 83883 | I11: 515374 | J11: =D11+G11+H11+I11 -> 45760932 | K11: =IFERROR(J11/E11,0) -> 10.740942 | L11: =IFERROR(C11/E11,0) -> 0.29046543 | M11: =J11/1000000 -> 45.760932 | N11: 1152470 | O11: 40336450 | P11: 3883957.5 | Q11: =O11/P11 -> 10.385399 | R11: 1848000 | S11: 179 | T11: 447003 | U11: =O11+R11+S11+T11 -> 42631632 | V11: =IFERROR(U11/P11,0) -> 10.976338 | W11: =IFERROR(N11/P11,0) -> 0.2967257 | X11: =U11/1000000 -> 42.631632 | Y11: =U11-J11 -> -3129300 | Z11: =V11-K11 -> 0.23539686 | AA11: =W11-L11 -> 0.0062602653
A12: สิงหาคม | B12: Aug | C12: 1355800 | D12: 47453000 | E12: 5011388.9 | F12: =D12/E12 -> 9.4690316 | G12: 1849000 | H12: 13000 | I12: 533843 | J12: =D12+G12+H12+I12 -> 49848843 | K12: =IFERROR(J12/E12,0) -> 9.9471113 | L12: =IFERROR(C12/E12,0) -> 0.27054376 | M12: =J12/1000000 -> 49.848843 | N12: 1056446.8 | O12: 36975638 | P12: 3768636.1 | Q12: =O12/P12 -> 9.8114112 | R12: 1848000 | S12: 65820 | T12: 389529 | U12: =O12+R12+S12+T12 -> 39278987 | V12: =IFERROR(U12/P12,0) -> 10.4226 | W12: =IFERROR(N12/P12,0) -> 0.28032603 | X12: =U12/1000000 -> 39.278987 | Y12: =U12-J12 -> -10569856 | Z12: =V12-K12 -> 0.47548893 | AA12: =W12-L12 -> 0.0097822728
A13: กันยายน | B13: Sep | C13: 1096326 | D13: 38371410 | E13: 3744024.9 | F13: =D13/E13 -> 10.248706 | G13: 1849000 | H13: 86640 | I13: 403001 | J13: =D13+G13+H13+I13 -> 40710051 | K13: =IFERROR(J13/E13,0) -> 10.873339 | L13: =IFERROR(C13/E13,0) -> 0.29282017 | M13: =J13/1000000 -> 40.710051 | N13: 689541 | O13: 24133935 | P13: 2437076.9 | Q13: =O13/P13 -> 9.9028205 | R13: 1848000 | S13: 89000 | T13: 437840 | U13: =O13+R13+S13+T13 -> 26508775 | V13: =IFERROR(U13/P13,0) -> 10.877283 | W13: =IFERROR(N13/P13,0) -> 0.28293773 | X13: =U13/1000000 -> 26.508775 | Y13: =U13-J13 -> -14201276 | Z13: =V13-K13 -> 0.003944202 | AA13: =W13-L13 -> -0.0098824404
A14: ตุลาคม | B14: Oct | C14: 1050478 | D14: 36766730 | E14: 3708245.9 | F14: =D14/E14 -> 9.9148576 | G14: 1849000 | H14: 6430 | I14: 357345 | J14: =D14+G14+H14+I14 -> 38979505 | K14: =IFERROR(J14/E14,0) -> 10.511575 | L14: =IFERROR(C14/E14,0) -> 0.28328165 | M14: =J14/1000000 -> 38.979505 | N14: 580650 | O14: 20322750 | P14: 2009742.7 | Q14: =O14/P14 -> 10.112115 | R14: 1848000 | S14: 0 | T14: 0 | U14: =O14+R14+S14+T14 -> 22170750 | V14: =IFERROR(U14/P14,0) -> 11.031636 | W14: =IFERROR(N14/P14,0) -> 0.28891758 | X14: =U14/1000000 -> 22.17075 | Y14: =U14-J14 -> -16808755 | Z14: =V14-K14 -> 0.52006101 | AA14: =W14-L14 -> 0.005635936
A15: พฤศจิกายน | B15: Nov | C15: 978803 | D15: 34258105 | E15: 3285198.5 | F15: =D15/E15 -> 10.428017 | G15: 1849000 | H15: 40460 | I15: 405798 | J15: =D15+G15+H15+I15 -> 36553363 | K15: =IFERROR(J15/E15,0) -> 11.126683 | L15: =IFERROR(C15/E15,0) -> 0.29794334 | M15: =J15/1000000 -> 36.553363 | N15: 262273.42 | O15: 9179569.7 | P15: 911185.7 | Q15: =O15/P15 -> 10.074313 | R15: 1848000 | S15: 0 | T15: 0 | U15: =O15+R15+S15+T15 -> 11027570 | V15: =IFERROR(U15/P15,0) -> 12.102439 | W15: =IFERROR(N15/P15,0) -> 0.28783751 | X15: =U15/1000000 -> 11.02757 | Y15: =U15-J15 -> -25525793 | Z15: =V15-K15 -> 0.97575617 | AA15: =W15-L15 -> -0.010105829
A16: ธันวาคม | B16: Dec | C16: 1046974 | D16: 36644090 | E16: 3600948.8 | F16: =D16/E16 -> 10.176232 | G16: 1849000 | H16: 17645 | I16: 283965 | J16: =D16+G16+H16+I16 -> 38794700 | K16: =IFERROR(J16/E16,0) -> 10.773466 | L16: =IFERROR(C16/E16,0) -> 0.29074948 | M16: =J16/1000000 -> 38.7947 | N16: 321539 | O16: 11253865 | P16: 1115485.2 | Q16: =O16/P16 -> 10.088762 | R16: 1848000 | S16: 0 | T16: 0 | U16: =O16+R16+S16+T16 -> 13101865 | V16: =IFERROR(U16/P16,0) -> 11.74544 | W16: =IFERROR(N16/P16,0) -> 0.28825035 | X16: =U16/1000000 -> 13.101865 | Y16: =U16-J16 -> -25692835 | Z16: =V16-K16 -> 0.97197431 | AA16: =W16-L16 -> -0.0024991319
A17: รวม | B17: Total | C17: =SUM(C5:C16) -> 14192874 | D17: =SUM(D5:D16) -> 496750590 | E17: =SUM(E5:E16) -> 49151176 | F17: =D17/E17 -> 10.106586 | G17: =SUM(G5:G16) -> 22194000 | H17: =SUM(H5:H16) -> 325294 | I17: =SUM(I5:I16) -> 5540104 | J17: =SUM(J5:J16) -> 524809988 | K17: =IFERROR(J17/E17,0) -> 10.677466 | L17: =IFERROR(C17/E17,0) -> 0.2887596 | M17: =SUM(M5:M16) -> 524.80999 | N17: =SUM(N5:N16) -> 11405723 | O17: =SUM(O5:O16) -> 3.9920031e+08 | P17: =SUM(P5:P16) -> 39377866 | Q17: =O17/P17 -> 10.137683 | R17: =SUM(R5:R16) -> 22176000 | S17: =SUM(S5:S16) -> 649068.34 | T17: =SUM(T5:T16) -> 3409094 | U17: =SUM(U5:U16) -> 4.2543448e+08 | V17: =IFERROR(U17/P17,0) -> 10.803899 | W17: =IFERROR(N17/P17,0) -> 0.28964808 | X17: =SUM(X5:X16) -> 425.43448 | Y17: =SUM(Y5:Y16) -> -99375513 | Z17: =V17-K17 -> 0.1264333 | AA17: =W17-L17 -> 0.00088848089
E19: ค่าเฉลี่ย (THB/kWh) | F19: =AVERAGE(F5:F16) -> 10.121941 | L19: =AVERAGE(L5:L16) -> 0.28919833 | P19: ค่าเฉลี่ย (THB/kWh) | Q19: =AVERAGE(Q5:Q16) -> 10.119787 | W19: =AVERAGE(W5:W16) -> 0.28913678
E20: Energy (kWh) 2567 | F20: Fuel Cost /Energy | G20: Fuel Cost (บาท) จากการอิงค่า 10.12 | H20: Error bath | I20: AbsError_bath | J20: % error | P20: Energy (kWh) 2568 | Q20: Fuel Cost /Energy | R20: Fuel Cost (บาท) จากการอิงค่า 10.12 | S20: Error bath | T20: AbsError_bath | U20: % error
E21: 3686134 | F21: =F19 -> 10.121941 | G21: =E21*F21 -> 37310833 | H21: =D5-G21 -> 230062.36 | I21: =ABS(H21) -> 230062.36 | J21: =IF(D5=0,"",I21/D5)*100 -> 0.6128313 | K21: Weighted average | L21: =(D17+O17)/(E17+P17) -> 10.120418 | P21: 3992188 | Q21: =Q19 -> 10.119787 | R21: =P21*Q21 -> 40400094 | S21: =O5-R21 -> 533351.01 | T21: =ABS(S21) -> 533351.01 | U21: =IF(O5=0,"",T21/O5)*100 -> 1.3029712
E22: 3823863.6 | F22: =F21 -> 10.121941 | G22: =E22*F22 -> 38704924 | H22: =D6-G22 -> 154701.4 | I22: =ABS(H22) -> 154701.4 | J22: =IF(D6=0,"",I22/D6)*100 -> 0.39810318 | P22: 3716275.5 | Q22: =Q21 -> 10.119787 | R22: =P22*Q22 -> 37607918 | S22: =O6-R22 -> 275766.87 | T22: =ABS(S22) -> 275766.87 | U22: =IF(O6=0,"",T22/O6)*100 -> 0.72793042
E23: 4647498.7 | F23: =F22 -> 10.121941 | G23: =E23*F23 -> 47041709 | H23: =D7-G23 -> 278955.62 | I23: =ABS(H23) -> 278955.62 | J23: =IF(D7=0,"",I23/D7)*100 -> 0.58950064 | P23: 4670596.9 | Q23: =Q22 -> 10.119787 | R23: =P23*Q23 -> 47265448 | S23: =O7-R23 -> -544963.26 | T23: =ABS(S23) -> 544963.26 | U23: =IF(O7=0,"",T23/O7)*100 -> 1.1664332
E24: 4892890.5 | F24: =F23 -> 10.121941 | G24: =E24*F24 -> 49525551 | H24: =D8-G24 -> 311963.68 | I24: =ABS(H24) -> 311963.68 | J24: =IF(D8=0,"",I24/D8)*100 -> 0.62596154 | P24: 4630957.3 | Q24: =Q23 -> 10.119787 | R24: =P24*Q24 -> 46864304 | S24: =O8-R24 -> 1267801.5 | T24: =ABS(S24) -> 1267801.5 | U24: =IF(O8=0,"",T24/O8)*100 -> 2.6340038
E25: 4595579.4 | F25: =F24 -> 10.121941 | G25: =E25*F25 -> 46516186 | H25: =D9-G25 -> 315879.03 | I25: =ABS(H25) -> 315879.03 | J25: =IF(D9=0,"",I25/D9)*100 -> 0.67449307 | P25: 4301887 | Q25: =Q24 -> 10.119787 | R25: =P25*Q25 -> 43534182 | S25: =O9-R25 -> 73402.962 | T25: =ABS(S25) -> 73402.962 | U25: =IF(O9=0,"",T25/O9)*100 -> 0.16832614
E26: 3894982 | F26: =F25 -> 10.121941 | G26: =E26*F26 -> 39424780 | H26: =D10-G26 -> 129035.12 | I26: =ABS(H26) -> 129035.12 | J26: =IF(D10=0,"",I26/D10)*100 -> 0.32622674 | P26: 3939876.7 | Q26: =Q25 -> 10.119787 | R26: =P26*Q26 -> 39870715 | S26: =O10-R26 -> -149914.75 | T26: =ABS(S26) -> 149914.75 | U26: =IF(O10=0,"",T26/O10)*100 -> 0.37742128
E27: 4260420.9 | F27: =F26 -> 10.121941 | G27: =E27*F27 -> 43123731 | H27: =D11-G27 -> 188943.96 | I27: =ABS(H27) -> 188943.96 | J27: =IF(D11=0,"",I27/D11)*100 -> 0.43623249 | P27: 3883957.5 | Q27: =Q26 -> 10.119787 | R27: =P27*Q27 -> 39304824 | S27: =O11-R27 -> 1031625.7 | T27: =ABS(S27) -> 1031625.7 | U27: =IF(O11=0,"",T27/O11)*100 -> 2.557552
E28: 5011388.9 | F28: =F27 -> 10.121941 | G28: =E28*F28 -> 50724985 | H28: =D12-G28 -> -3271985.2 | I28: =ABS(H28) -> 3271985.2 | J28: =IF(D12=0,"",I28/D12)*100 -> 6.8952125 | P28: 3768636.1 | Q28: =Q27 -> 10.119787 | R28: =P28*Q28 -> 38137796 | S28: =O12-R28 -> -1162157.9 | T28: =ABS(S28) -> 1162157.9 | U28: =IF(O12=0,"",T28/O12)*100 -> 3.1430368
E29: 3744024.9 | F29: =F28 -> 10.121941 | G29: =E29*F29 -> 37896801 | H29: =D13-G29 -> 474609.05 | I29: =ABS(H29) -> 474609.05 | J29: =IF(D13=0,"",I29/D13)*100 -> 1.236882 | P29: 2437076.9 | Q29: =Q28 -> 10.119787 | R29: =P29*Q29 -> 24662700 | S29: =O13-R29 -> -528765.21 | T29: =ABS(S29) -> 528765.21 | U29: =IF(O13=0,"",T29/O13)*100 -> 2.1909614
E30: 3708245.9 | F30: =F29 -> 10.121941 | G30: =E30*F30 -> 37534648 | H30: =D14-G30 -> -767918 | I30: =ABS(H30) -> 767918 | J30: =IF(D14=0,"",I30/D14)*100 -> 2.088622 | P30: 2009742.7 | Q30: =Q29 -> 10.119787 | R30: =P30*Q30 -> 20338169 | S30: =O14-R30 -> -15418.936 | T30: =ABS(S30) -> 15418.936 | U30: =IF(O14=0,"",T30/O14)*100 -> 0.075870324
E31: 3285198.5 | F31: =F30 -> 10.121941 | G31: =E31*F31 -> 33252587 | H31: =D15-G31 -> 1005518 | I31: =ABS(H31) -> 1005518 | J31: =IF(D15=0,"",I31/D15)*100 -> 2.9351245 | P31: 911185.7 | Q31: =Q30 -> 10.119787 | R31: =P31*Q31 -> 9221005.6 | S31: =O15-R31 -> -41435.904 | T31: =ABS(S31) -> 41435.904 | U31: =IF(O15=0,"",T31/O15)*100 -> 0.45139266
E32: 3600948.8 | F32: =F31 -> 10.121941 | G32: =E32*F32 -> 36448593 | H32: =D16-G32 -> 195496.96 | I32: =ABS(H32) -> 195496.96 | J32: =IF(D16=0,"",I32/D16)*100 -> 0.53350203 | P32: 1115485.2 | Q32: =Q31 -> 10.119787 | R32: =P32*Q32 -> 11288473 | S32: =O16-R32 -> -34608.118 | T32: =ABS(S32) -> 34608.118 | U32: =IF(O16=0,"",T32/O16)*100 -> 0.30752207
E33: =SUM(E21:E32) -> 49151176 | F33: =F32 -> 10.121941 | G33: =E33*F33 -> 4.9750533e+08 | H33: =D17-G33 -> -754737.98 | I33: =ABS(H33) -> 754737.98 | J33: =IF(D17=0,"",I33/D17)*100 -> 0.15193499 | P33: =SUM(P21:P32) -> 39377866 | Q33: =Q32 -> 10.119787 | R33: =P33*Q33 -> 3.9849563e+08 | S33: =O17-R33 -> 704683.88 | T33: =ABS(S33) -> 704683.88 | U33: =IF(O17=0,"",T33/O17)*100 -> 0.17652388
E36: All-in (THB/kWh) 2567 | F36: Fuel Intensity (L/kWh) 2567 | G36: THB/L | P36: All-in (THB/kWh) 2568 | Q36: All-in (THB/kWh) 2568 | R36: THB/L
E37: =K5 -> 10.803018 | F37: =L5 -> 0.29098155 | G37: =E37/F37 -> 37.126126 | K37: Weighted average | L37: =AVERAGE(G51,R51) -> 37.455222 | P37: =V5 -> 10.797316 | Q37: =W5 -> 0.29295389 | R37: =P37/Q37 -> 36.856709
E38: =K6 -> 10.780425 | F38: =L6 -> 0.29035424 | G38: =E38/F38 -> 37.128527 | P38: =V6 -> 10.893027 | Q38: =W6 -> 0.29125693 | R38: =P38/Q38 -> 37.400059
E39: =K7 -> 10.684232 | F39: =L7 -> 0.29091326 | G39: =E39/F39 -> 36.726522 | P39: =V7 -> 10.467601 | Q39: =W7 -> 0.28580308 | R39: =P39/Q39 -> 36.625221
E40: =K8 -> 10.675381 | F40: =L8 -> 0.29102 | G40: =E40/F40 -> 36.682637 | K40: Weighted average | L40: =AVERAGE(L19,W19) -> 0.28916756 | P40: =V8 -> 10.889119 | Q40: =W8 -> 0.29695869 | R40: =P40/Q40 -> 36.668802
E41: =K9 -> 10.711653 | F41: =L9 -> 0.2911622 | G41: =E41/F41 -> 36.789297 | P41: =V9 -> 10.648381 | Q41: =W9 -> 0.2896243 | R41: =P41/Q41 -> 36.766187
E42: =K10 -> 10.784048 | F42: =L10 -> 0.29014486 | G42: =E42/F42 -> 37.167806 | P42: =V10 -> 10.661087 | Q42: =W10 -> 0.28804962 | R42: =P42/Q42 -> 37.011286
E43: =K11 -> 10.740942 | F43: =L11 -> 0.29046543 | G43: =E43/F43 -> 36.978382 | P43: =V11 -> 10.976338 | Q43: =W11 -> 0.2967257 | R43: =P43/Q43 -> 36.991533
E44: =K12 -> 9.9471113 | F44: =L12 -> 0.27054376 | G44: =E44/F44 -> 36.767107 | P44: =V12 -> 10.4226 | Q44: =W12 -> 0.28032603 | R44: =P44/Q44 -> 37.180279
...

Sheet Summary_Improvement ปึ 67 vs 68
A1: Annual KPI Summary
A3: Metric | B3: 2567 | C3: 2568 | D3: Δ (2568-2567) | E3: %Δ vs 2567
A4: Energy (GWh) | B4: =Inputs!E17/1000000 -> 49.151176 | C4: =Inputs!P17/1000000 -> 39.377866 | D4: =C4-B4 -> -9.7733105 | E4: =IFERROR(D4/B4,0) -> -0.19884184
A5: Fuel (Million L) | B5: =Inputs!C17/1000000 -> 14.192874 | C5: =Inputs!N17/1000000 -> 11.405723 | D5: =C5-B5 -> -2.7871508 | E5: =IFERROR(D5/B5,0) -> -0.19637677
A6: Fuel cost (Million THB) | B6: =Inputs!D17/1000000 -> 496.75059 | C6: =Inputs!O17/1000000 -> 399.20031 | D6: =C6-B6 -> -97.550277 | E6: =IFERROR(D6/B6,0) -> -0.19637677
A7: Rental (Million THB) | B7: =Inputs!G17/1000000 -> 22.194 | C7: =Inputs!R17/1000000 -> 22.176 | D7: =C7-B7 -> -0.018 | E7: =IFERROR(D7/B7,0) -> -0.00081103001
A8: Maintenance (Million THB) | B8: =Inputs!H17/1000000 -> 0.325294 | C8: =Inputs!S17/1000000 -> 0.64906834 | D8: =C8-B8 -> 0.32377434 | E8: =IFERROR(D8/B8,0) -> 0.99532835
A9: Other (Million THB) | B9: =Inputs!I17/1000000 -> 5.540104 | C9: =Inputs!T17/1000000 -> 3.409094 | D9: =C9-B9 -> -2.13101 | E9: =IFERROR(D9/B9,0) -> -0.38465162
A10: Total cost (Million THB) | B10: =Inputs!J17/1000000 -> 524.80999 | C10: =Inputs!U17/1000000 -> 425.43448 | D10: =C10-B10 -> -99.375513 | E10: =IFERROR(D10/B10,0) -> -0.18935522
A11: All-in cost (THB/kWh) | B11: =Inputs!K17 -> 10.677466 | C11: =Inputs!V17 -> 10.803899 | D11: =C11-B11 -> 0.1264333 | E11: =IFERROR(D11/B11,0) -> 0.011841134
A12: Fuel intensity (L/kWh) | B12: =Inputs!L17 -> 0.2887596 | C12: =Inputs!W17 -> 0.28964808 | D12: =C12-B12 -> 0.00088848089 | E12: =IFERROR(D12/B12,0) -> 0.0030768878

Sheet Charts
A1: Standard Value Charts (2567 vs 2568)
A60: 4) Cost Breakdown (Annual, Million THB)
A62: Year | B62: Fuel | C62: Rental | D62: Maintenance | E62: Other
A63: 2567 | B63: =Inputs!D17/1000000 -> 496.75059 | C63: =Inputs!G17/1000000 -> 22.194 | D63: =Inputs!H17/1000000 -> 0.325294 | E63: =Inputs!I17/1000000 -> 5.540104
A64: 2568 | B64: =Inputs!O17/1000000 -> 399.20031 | C64: =Inputs!R17/1000000 -> 22.176 | D64: =Inputs!S17/1000000 -> 0.64906834 | E64: =Inputs!T17/1000000 -> 3.409094
